<?xml version="1.0" ?>
<!-- =================================================================================== -->
<!-- |    This document was autogenerated by xacro from intel_robot.urdf.xacro         | -->
<!-- |    EDITING THIS FILE BY HAND IS NOT RECOMMENDED                                 | -->
<!-- =================================================================================== -->
<robot name="intel_robot" xmlns:xacro="http://ros.org/wiki/xacro">
  <link name="base_link">
    <visual>
      <geometry>
        <cylinder length="0.1" radius="0.1"/>
      </geometry>
      <origin xyz="0 0 0"/>
    </visual>
    <collision>
      <origin xyz="0 0 0.0"/>
      <geometry>
        <cylinder length="0.1" radius="0.1"/>
      </geometry>
    </collision>
    <!--xacro:caster suffix="front" reflect="1"/>
  <xacro:caster suffix="back" reflect="-1"/-->
  </link>
  <gazebo reference="base_link">
    <gravity>true</gravity>
    <material>Gazebo/Blue</material>
    <sensor name="imu_sensor" type="imu">
      <always_on>true</always_on>
      <update_rate>100</update_rate>
      <visualize>true</visualize>
      <topic>__default_topic__</topic>
      <plugin filename="libgazebo_ros_imu_sensor.so" name="imu_plugin">
        <topicName>imu</topicName>
        <bodyName>imu_link</bodyName>
        <updateRateHZ>10.0</updateRateHZ>
        <gaussianNoise>0.0</gaussianNoise>
        <xyzOffset>0 0 0</xyzOffset>
        <rpyOffset>0 0 0</rpyOffset>
        <frameName>imu_link</frameName>
      </plugin>
      <pose>0 0 0 0 0 0</pose>
    </sensor>
  </gazebo>
  <link name="front_caster_link">
    <visual>
      <geometry>
        <sphere radius="0.012"/>
      </geometry>
      <origin rpy="0 0 0" xyz="0.0875 0 -0.0625"/>
      <material name="black"/>
    </visual>
    <!--surface>
            <friction>
              <ode>
                <mu>0</mu>
                <mu2>0</mu2>
                <slip1>1.0</slip1>
                <slip2>1.0</slip2>
              </ode>
            </friction>
          </surface-->
    <collision>
      <origin rpy="0  0  0" xyz="0.0875 0 -0.0625"/>
      <geometry>
        <sphere radius="0.012"/>
      </geometry>
    </collision>
    <inertial>
      <mass value="0.2"/>
      <inertia ixx="1.152e-05" ixy="0.0" ixz="0.0" iyy="1.152e-05" iyz="0.0" izz="1.152e-05"/>
    </inertial>
  </link>
  <joint name="casterf_to_base" type="fixed">
    <axis xyz="1 1 1"/>
    <parent link="base_link"/>
    <child link="front_caster_link"/>
    <origin xyz="0 0 0"/>
  </joint>
  <link name="back_caster_link">
    <visual>
      <geometry>
        <sphere radius="0.012"/>
      </geometry>
      <origin rpy="0 0 0" xyz="-0.0875 0 -0.0625"/>
      <material name="black"/>
    </visual>
    <!--surface>
            <friction>
              <ode>
                <mu>0</mu>
                <mu2>0</mu2>
                <slip1>1.0</slip1>
                <slip2>1.0</slip2>
              </ode>
            </friction>
          </surface-->
    <collision>
      <origin rpy="0  0  0" xyz="-0.0875 0 -0.0625"/>
      <geometry>
        <sphere radius="0.012"/>
      </geometry>
    </collision>
    <inertial>
      <mass value="0.2"/>
      <inertia ixx="1.152e-05" ixy="0.0" ixz="0.0" iyy="1.152e-05" iyz="0.0" izz="1.152e-05"/>
    </inertial>
  </link>
  <gazebo reference="front_caster_link">
    <mu1 value="0.0"/>
    <mu2 value="0.0"/>
    <kp value="10000000.0"/>
    <kd value="1.0"/>
    <material>Gazebo/Black</material>
  </gazebo>
  <transmission name="front_caster_wheel_trans">
    <type>transmission_interface/SimpleTransmission</type>
    <actuator name="front_caster_wheel_motor">
      <hardwareInterface>EffortJointInterface</hardwareInterface>
      <mechanicalReduction>1</mechanicalReduction>
    </actuator>
    <joint name="casterf_to_base">
      <hardwareInterface>VelocityJointInterface</hardwareInterface>
    </joint>
  </transmission>
  <joint name="casterb_to_base" type="fixed">
    <axis xyz="1 1 1"/>
    <parent link="base_link"/>
    <child link="back_caster_link"/>
    <origin xyz="0 0 0"/>
  </joint>
  <gazebo reference="back_caster_link">
    <mu1 value="0.0"/>
    <mu2 value="0.0"/>
    <kp value="10000000.0"/>
    <kd value="1.0"/>
    <material>Gazebo/Black</material>
  </gazebo>
  <transmission name="back_caster_wheel_trans">
    <type>transmission_interface/SimpleTransmission</type>
    <actuator name="back_caster_wheel_motor">
      <hardwareInterface>EffortJointInterface</hardwareInterface>
      <mechanicalReduction>1</mechanicalReduction>
    </actuator>
    <joint name="casterb_to_base">
      <hardwareInterface>VelocityJointInterface</hardwareInterface>
    </joint>
  </transmission>
  <link name="top_link">
    <visual>
      <geometry>
        <cylinder length="0.5" radius="0.1"/>
      </geometry>
      <origin xyz="0 0 0.25"/>
    </visual>
    <collision>
      <origin rpy="0 0 0" xyz="0 0 0.25"/>
      <geometry>
        <cylinder length="0.5" radius="0.1"/>
      </geometry>
    </collision>
    <inertial>
      <mass value="8"/>
      <inertia ixx="0.186666666667" ixy="0.0" ixz="0.0" iyy="0.186666666667" iyz="0.0" izz="0.04"/>
    </inertial>
  </link>
  <gazebo reference="top_link">
    <gravity value="True"/>
    <material>Gazebo/Red</material>
  </gazebo>
  <joint name="base_to_top" type="fixed">
    <parent link="base_link"/>
    <child link="top_link"/>
    <origin xyz="0 0 0.05"/>
  </joint>
  <link name="scooter_right_wheel">
    <visual>
      <origin rpy="1.57 0 0" xyz="0 0 0"/>
      <geometry>
        <cylinder length="0.025" radius="0.025"/>
      </geometry>
      <material name="black"/>
    </visual>
    <collision>
      <origin rpy="1.57 0 0" xyz="0 0 0"/>
      <geometry>
        <cylinder length="0.025" radius="0.025"/>
      </geometry>
    </collision>
    <inertial>
      <mass value="0.2"/>
      <inertia ixx="1.38888888889e-05" ixy="0.0" ixz="0.0" iyy="1.38888888889e-05" iyz="0.0" izz="6.94444444444e-06"/>
    </inertial>
  </link>
  <joint name="scooter_right_wheel_joint" type="continuous">
    <axis rpy="0 0 0" xyz="0 1 0"/>
    <parent link="base_link"/>
    <child link="scooter_right_wheel"/>
    <origin rpy="0 0 0" xyz="0 -0.1126 -0.05"/>
    <dynamics damping="0.20" friction="0.90"/>
    <limit effort="1000000" velocity="1000000"/>
  </joint>
  <gazebo reference="scooter_right_wheel">
    <mu1 value="1.0"/>
    <mu2 value="1.0"/>
    <kp value="10000000.0"/>
    <kd value="1.0"/>
    <material>Gazebo/Black</material>
  </gazebo>
  <transmission name="scooter_right_wheel_trans">
    <type>transmission_interface/SimpleTransmission</type>
    <actuator name="scooter_right_wheel_motor">
      <hardwareInterface>EffortJointInterface</hardwareInterface>
      <mechanicalReduction>1</mechanicalReduction>
    </actuator>
    <joint name="scooter_right_wheel_joint">
      <hardwareInterface>VelocityJointInterface</hardwareInterface>
    </joint>
  </transmission>
  <link name="scooter_left_wheel">
    <visual>
      <origin rpy="1.57 0 0" xyz="0 0 0"/>
      <geometry>
        <cylinder length="0.025" radius="0.025"/>
      </geometry>
      <material name="black"/>
    </visual>
    <collision>
      <origin rpy="1.57 0 0" xyz="0 0 0"/>
      <geometry>
        <cylinder length="0.025" radius="0.025"/>
      </geometry>
    </collision>
    <inertial>
      <mass value="0.2"/>
      <inertia ixx="1.38888888889e-05" ixy="0.0" ixz="0.0" iyy="1.38888888889e-05" iyz="0.0" izz="6.94444444444e-06"/>
    </inertial>
  </link>
  <joint name="scooter_left_wheel_joint" type="continuous">
    <axis rpy="0 0 0" xyz="0 1 0"/>
    <parent link="base_link"/>
    <child link="scooter_left_wheel"/>
    <origin rpy="0 0 0" xyz="0 0.1126 -0.05"/>
    <dynamics damping="0.20" friction="0.90"/>
    <limit effort="1000000" velocity="1000000"/>
  </joint>
  <gazebo reference="scooter_left_wheel">
    <mu1 value="1.0"/>
    <mu2 value="1.0"/>
    <kp value="10000000.0"/>
    <kd value="1.0"/>
    <material>Gazebo/Black</material>
  </gazebo>
  <transmission name="scooter_left_wheel_trans">
    <type>transmission_interface/SimpleTransmission</type>
    <actuator name="scooter_left_wheel_motor">
      <hardwareInterface>EffortJointInterface</hardwareInterface>
      <mechanicalReduction>1</mechanicalReduction>
    </actuator>
    <joint name="scooter_left_wheel_joint">
      <hardwareInterface>VelocityJointInterface</hardwareInterface>
    </joint>
  </transmission>
  <gazebo>
    <plugin filename="libgazebo_ros_control.so" name="gazebo_ros_control">
      <robotNamespace>/</robotNamespace>
    </plugin>
  </gazebo>
</robot>
