<?xml version="1.0"?>
<robot name="roscontrol" xmlns:xacro="http://ros.org/wiki/xacro">



<xacro:property name="bodyrad" value="0.1"/>
<xacro:property name="baselen" value="0.1"/>
<xacro:property name="base_mass" value="1"/>
<xacro:property name="toplen" value="0.5"/>
<xacro:property name="top_mass" value="8"/>
<xacro:property name="wheelrad" value="0.025"/>
<xacro:property name="wheelwidth" value="0.025"/>
<xacro:property name="casterrad" value="0.012"/>
<xacro:property name="caster_mass" value="0.2"/>
<xacro:property name="wheel_mass" value="0.2"/>

 <xacro:macro name="default_inertial" params="mass">
    <inertial>
      <mass value="${mass}" />
      <inertia ixx="1.0" ixy="0.0" ixz="0.0" iyy="1.0" iyz="0.0" izz="1.0" />
    </inertial>
  </xacro:macro>
<xacro:macro name="cylinder_inertia" params ="m r h">
  <inertial>
   <mass value="${m}"/>
   <inertia ixx="${m*(3*r*r+h*h)/12}"  ixy="0.0" ixz="0.0"
            iyy="${m*(3*r*r+h*h)/12}"  iyz= "0.0"
            izz="${m*r*r/2}"/>
   </inertial>
</xacro:macro>

<xacro:macro name="sphere_inertia" params ="m r">
  <inertial>
   <mass value="${m}"/>
   <inertia ixx="${m*(r*r*2)/5}"  ixy="0.0" ixz="0.0"
            iyy="${m*(r*r*2)/5}"  iyz= "0.0"
            izz="${m*(r*r*2)/5}"/>
   </inertial>
</xacro:macro>


<xacro:macro name="caster" params="suffix reflect">
<link name="${suffix}_caster_link">
  <visual>
   <geometry>
     <sphere radius="${casterrad}"/>
     </geometry>
     <origin rpy="0 0 0" xyz="${reflect*0.0875} 0 -0.0624"/>
     <material name="black"/>
    </visual>
    <surface>
            <friction>
              <ode>
                <mu>0.0</mu>
                <mu2>0.0</mu2>
                <!-- <slip1>1.0</slip1>
                <slip2>1.0</slip2> -->
              </ode>
            </friction>
          </surface>
    <collision>
    <origin rpy="0  0  0" xyz="${reflect*0.0875} 0 -0.0624"/>
      <geometry>
        <sphere radius="${casterrad}" />
      </geometry>
    </collision>
   <xacro:sphere_inertia m="${caster_mass}" r="${casterrad}"/>
  </link>
</xacro:macro>




<link name="base_link">
    <visual>
      <geometry>
        <cylinder length="${baselen}" radius="${bodyrad}" />
      </geometry>
      <origin xyz="0 0 0"/>
    </visual>
    
    <collision>
      <origin xyz="0 0 0.0"/>
      <geometry>
        <cylinder length="${baselen}" radius="${bodyrad}" />
      </geometry>
    </collision>
  
  </link>

  <gazebo reference="base_link">
    <gravity>true</gravity>
    <material>Gazebo/Blue</material>
    <sensor name="imu_sensor" type="imu">
      <always_on>true</always_on>
      <update_rate>100</update_rate>
      <visualize>true</visualize>
      <topic>__default_topic__</topic>
      <plugin filename="libgazebo_ros_imu_sensor.so" name="imu_plugin">
        <topicName>imu</topicName>
        <bodyName>imu_link</bodyName>
        <updateRateHZ>10.0</updateRateHZ>
        <gaussianNoise>0.0</gaussianNoise>
        <xyzOffset>0 0 0</xyzOffset>
        <rpyOffset>0 0 0</rpyOffset>
        <frameName>imu_link</frameName>
      </plugin>
      <pose>0 0 0 0 0 0</pose>
    </sensor>
  </gazebo>

<xacro:caster suffix="front" reflect="1"/>

<joint name="casterf_to_base" type="fixed">
    <axis xyz="1 1 1"/>
    <parent link="base_link"/>
    <child link="front_caster_link"/>
    <origin xyz="0 0 0"/>
</joint>


<gazebo reference="front_caster_link">
      <surface>
            <friction>
              <ode>
                <mu>0.005</mu>
                <mu2>0.005</mu2>
                <!-- <slip1>1</slip1>
                <slip2>1</slip2> -->
              </ode>
            </friction>
          </surface>
      <material>Gazebo/Black</material>
     </gazebo>


<xacro:caster suffix="back" reflect="-1"/>

<joint name="casterb_to_base" type="fixed">
    <axis xyz="1 1 1"/>
    <parent link="base_link"/>
    <child link="back_caster_link"/>
    <origin xyz="0 0 0"/>
</joint>

<gazebo reference="back_caster_link">
     <surface>
            <friction>
              <ode>
                <mu>0.005</mu>
                <mu2>0.005</mu2>
                <!-- <slip1>0.5</slip1>
                <slip2>0.5</slip2> -->
              </ode>
            </friction>
          </surface>
      <material>Gazebo/Black</material>
     </gazebo>


<link name="top_link">
    <visual>
      <geometry>
        <cylinder radius="${bodyrad}" length="${toplen}"/>
      </geometry>
      <origin xyz="0 0 0.25" />
     </visual>
    <collision>
      <origin xyz="0 0 0.25" rpy="0 0 0" />
      <geometry>
        <cylinder radius="${bodyrad}" length="${toplen}"/>
      </geometry>
    </collision>
    <xacro:cylinder_inertia m="${top_mass}" r="${bodyrad}" h="${toplen}"/>
</link>


<gazebo reference="top_link">
      <gravity value="True"/>
      <material>Gazebo/Red</material>
    </gazebo>


<joint name="base_to_top" type="fixed">
    <parent link="base_link"/>
    <child link="top_link"/>
    <origin xyz="0 0 0.05"/>
</joint>


<xacro:macro name="wheel" params="prefix suffix reflect">

    <link name="${prefix}_${suffix}_wheel">
      <visual>
        <origin rpy="1.57 0 0" xyz="0 0 0" />
        <geometry>
          <cylinder radius="${wheelrad}" length="${wheelwidth}"/>
        </geometry>
        <material name="black"/>
      </visual>
      <collision>
        <origin rpy="1.57 0 0" xyz="0 0 0"/>
        <geometry>
          <cylinder radius="${wheelrad}" length="${wheelwidth}"/>
        </geometry>
      </collision>
     <xacro:cylinder_inertia m="${wheel_mass}" r="${wheelrad/3}" h="${wheelwidth}"/>
    </link>
    <joint name="${prefix}_${suffix}_wheel_joint" type="continuous">
      <axis xyz="0 1 0" rpy="0 0 0" />
      <parent link="base_link"/>
      <child link="${prefix}_${suffix}_wheel"/>
      <origin xyz="0 ${reflect*0.1126} -0.05" rpy="0 0 0"/>
      <dynamics damping="0.20" friction="0.0"/>
      <limit effort="10000" velocity="30"/>
    </joint>
    <gazebo reference="${prefix}_${suffix}_wheel">
      <mu1 value="200.0"/>
      <mu2 value="100.0"/>
      <kp value="10000000.0" />
      <kd value="1.0" />
      <material>Gazebo/Black</material>
    </gazebo>


  <transmission name="${prefix}_${suffix}_wheel_trans">
    <type>transmission_interface/SimpleTransmission</type>
    <actuator name="${prefix}_${suffix}_wheel_motor">
    <hardwareInterface>EffortJointInterface</hardwareInterface>
      <mechanicalReduction>1</mechanicalReduction>
    </actuator>
    <joint name="${prefix}_${suffix}_wheel_joint">
    <hardwareInterface>hardware_interface/VelocityJointInterface</hardwareInterface>
    </joint>
  </transmission>

 </xacro:macro>


<xacro:wheel prefix="scooter" suffix="right" reflect="-1"/>
<xacro:wheel prefix="scooter" suffix="left" reflect="1"/>


<gazebo>
    <plugin name="gazebo_ros_control" filename="libgazebo_ros_control.so">
      <robotNamespace>/</robotNamespace>
    </plugin>
  </gazebo>



</robot>
